Workbook

Sheet CRFDraft
A1: DraftName | B1: DeleteExisting | C1: ProjectName | D1: ProjectType | E1: PrimaryFormOID | F1: DefaultMatrixOID | G1: ConfirmationMessage | H1: SignaturePrompt | I1: LabStandardGroup | J1: ReferenceLabs | K1: AlertLabs | L1: SyncOIDProject | M1: SyncOIDDraft | N1: SyncOIDProjectType | O1: SyncOIDOriginIsVersion | P1: SourceUrlId
A2: Version 1.1 | B2: FALSE | C2: CJ_DFM_102 | D2: Project | E2: SUBJECT | F2: SCRN | G2: 저장되었습니다. | H2: 시험대상자는 시험기간 중 본인의 감독 하에 있었으며, 본 증례기록서에 포함된 정보와 자료는 완벽하며 정확합니다. | N2: Project | O2: FALSE | P2: cuh | GR2: =IF(LEN(Forms!$A2)>0,Forms!$A2,"") -> SUBJECT
GR3: =IF(LEN(Forms!$A3)>0,Forms!$A3,"") -> DS1
GR4: =IF(LEN(Forms!$A4)>0,Forms!$A4,"") -> DM
GR5: =IF(LEN(Forms!$A5)>0,Forms!$A5,"") -> HO
GR6: =IF(LEN(Forms!$A6)>0,Forms!$A6,"") -> DS2
GR7: =IF(LEN(Forms!$A7)>0,Forms!$A7,"") -> MH
GR8: =IF(LEN(Forms!$A8)>0,Forms!$A8,"") -> SU1
GR9: =IF(LEN(Forms!$A9)>0,Forms!$A9,"") -> SU
GR10: =IF(LEN(Forms!$A10)>0,Forms!$A10,"") -> QS
GR11: =IF(LEN(Forms!$A11)>0,Forms!$A11,"") -> VS
GR12: =IF(LEN(Forms!$A12)>0,Forms!$A12,"") -> PE
GR13: =IF(LEN(Forms!$A13)>0,Forms!$A13,"") -> AEYN
GR14: =IF(LEN(Forms!$A14)>0,Forms!$A14,"") -> CMYN
... GR56: =IF(LEN(Forms!$A56)>0,Forms!$A56,"")

Sheet Forms
A1: OID | B1: Ordinal | C1: DraftFormName | D1: DraftFormActive | E1: HelpText | F1: IsTemplate | G1: IsSignatureRequired | H1: IsEproForm | I1: ViewRestrictions | J1: EntryRestrictions | K1: LogDirection | L1: DDEOption | M1: ConfirmationStyle | N1: LinkFolderOID | O1: LinkFormOID | P1: DownloadedFromObjectId | Q1: SourceObjectId | R1: SourceUrlId
A2: SUBJECT | B2: 1 | C2: 대상자등록 | D2: TRUE | F2: FALSE | G2: FALSE | H2: FALSE | L2: MustNotDDE | P2: 18324 | Q2: 17392 | GR2: =IF(LEN(Folders!$A2)>0,Folders!$A2,"") -> AE
A3: DS1 | B3: 6 | C3: 스크리닝 방문 | D3: TRUE | F3: FALSE | G3: TRUE | H3: FALSE | K3: Landscape | L3: MustNotDDE | P3: 18297 | Q3: 17368 | GR3: =IF(LEN(Folders!$A3)>0,Folders!$A3,"") -> CC
A4: DM | B4: 9 | C4: 인구학적 정보 | D4: TRUE | F4: FALSE | G4: TRUE | H4: FALSE | L4: MustNotDDE | P4: 18296 | Q4: 17367 | GR4: =IF(LEN(Folders!$A4)>0,Folders!$A4,"") -> CM
A5: HO | B5: 10 | C5: 입원일 | D5: TRUE | F5: FALSE | G5: TRUE | H5: FALSE | L5: MustNotDDE | P5: 18305 | Q5: 0 | GR5: =IF(LEN(Folders!$A5)>0,Folders!$A5,"") -> DV
A6: DS2 | B6: 11 | C6: 무작위배정번호 부여 | D6: TRUE | F6: FALSE | G6: TRUE | H6: FALSE | L6: MustNotDDE | P6: 18298 | Q6: 17369 | GR6: =IF(LEN(Folders!$A6)>0,Folders!$A6,"") -> P1D0
A7: MH | B7: 21 | C7: 병력/수술력 | D7: TRUE | F7: FALSE | G7: TRUE | H7: FALSE | K7: Portrait | L7: MustNotDDE | P7: 18313 | Q7: 17382 | GR7: =IF(LEN(Folders!$A7)>0,Folders!$A7,"") -> P1D0H12
A8: SU1 | B8: 22 | C8: 생활습관 확인(입원) | D8: TRUE | F8: FALSE | G8: TRUE | H8: FALSE | K8: Landscape | L8: MustNotDDE | P8: 18322 | Q8: 17390 | GR8: =IF(LEN(Folders!$A8)>0,Folders!$A8,"") -> P1D0H2
A9: SU | B9: 33 | C9: 생활습관 | D9: TRUE | F9: FALSE | G9: TRUE | H9: FALSE | L9: MustNotDDE | P9: 18321 | Q9: 17389 | GR9: =IF(LEN(Folders!$A9)>0,Folders!$A9,"") -> P1D0H4
A10: QS | B10: 47 | C10: 시험 전 면담 | D10: TRUE | F10: FALSE | G10: TRUE | H10: FALSE | K10: Landscape | L10: MustNotDDE | P10: 18319 | Q10: 17387 | GR10: =IF(LEN(Folders!$A10)>0,Folders!$A10,"") -> P1D0H8
A11: VS | B11: 62 | C11: 활력징후 | D11: TRUE | F11: FALSE | G11: TRUE | H11: FALSE | K11: Landscape | L11: MustNotDDE | P11: 18325 | Q11: 17393 | GR11: =IF(LEN(Folders!$A11)>0,Folders!$A11,"") -> P1D1H24
A12: PE | B12: 83 | C12: 신체검사 | D12: TRUE | F12: FALSE | G12: TRUE | H12: FALSE | K12: Portrait | L12: MustNotDDE | P12: 18318 | Q12: 17386 | GR12: =IF(LEN(Folders!$A12)>0,Folders!$A12,"") -> P1D1H36
A13: AEYN | B13: 84 | C13: 이상반응 확인 | D13: TRUE | F13: FALSE | G13: TRUE | H13: FALSE | L13: MustNotDDE | P13: 18292 | Q13: 17364 | GR13: =IF(LEN(Folders!$A13)>0,Folders!$A13,"") -> P1D2
A14: CMYN | B14: 85 | C14: 병용약물 확인 | D14: TRUE | F14: FALSE | G14: TRUE | H14: FALSE | L14: MustNotDDE | P14: 18295 | Q14: 17366 | GR14: =IF(LEN(Folders!$A14)>0,Folders!$A14,"") -> P1DM1
A15: LBHE | B15: 130 | C15: 혈액학검사 | D15: TRUE | F15: FALSE | G15: TRUE | H15: FALSE | L15: MustNotDDE | P15: 18309 | Q15: 17378 | GR15: =IF(LEN(Folders!$A15)>0,Folders!$A15,"") -> P2D6
A16: LBCH | B16: 174 | C16: 혈액화학검사 | D16: TRUE | F16: FALSE | G16: TRUE | H16: FALSE | L16: MustNotDDE | P16: 18308 | Q16: 17377 | GR16: =IF(LEN(Folders!$A16)>0,Folders!$A16,"") -> P2D7
A17: LBUR | B17: 219 | C17: 뇨검사 | D17: TRUE | F17: FALSE | G17: TRUE | H17: FALSE | L17: MustNotDDE | P17: 18311 | Q17: 17380 | GR17: =IF(LEN(Folders!$A17)>0,Folders!$A17,"") -> P2D7H12
A18: LBUR2 | B18: 220 | C18: 뇨검사(Others) | D18: TRUE | F18: FALSE | G18: TRUE | H18: FALSE | K18: Portrait | L18: MustNotDDE | P18: 18312 | Q18: 17381 | GR18: =IF(LEN(Folders!$A18)>0,Folders!$A18,"") -> P2D7H2
A19: LBBC | B19: 267 | C19: 혈액응고검사 | D19: TRUE | F19: FALSE | G19: TRUE | H19: FALSE | L19: MustNotDDE | P19: 18307 | Q19: 17376 | GR19: =IF(LEN(Folders!$A19)>0,Folders!$A19,"") -> P2D7H4
A20: LBSE | B20: 268 | C20: 혈청검사 | D20: TRUE | F20: FALSE | G20: TRUE | H20: FALSE | L20: MustNotDDE | P20: 18310 | Q20: 17379 | GR20: =IF(LEN(Folders!$A20)>0,Folders!$A20,"") -> P2D7H8
A21: RP | B21: 269 | C21: 임신반응검사 | D21: TRUE | F21: FALSE | G21: TRUE | H21: FALSE | K21: Landscape | L21: MustNotDDE | P21: 18320 | Q21: 17388 | GR21: =IF(LEN(Folders!$A21)>0,Folders!$A21,"") -> P2D8H24
A22: BST | B22: 270 | C22: 혈당검사 | D22: TRUE | F22: FALSE | G22: TRUE | H22: FALSE | K22: Landscape | L22: MustNotDDE | P22: 18293 | Q22: 17430 | GR22: =IF(LEN(Folders!$A22)>0,Folders!$A22,"") -> P2D8H36
A23: EG | B23: 274 | C23: 12-lead 심전도 | D23: TRUE | F23: FALSE | G23: TRUE | H23: FALSE | K23: Landscape | L23: MustNotDDE | P23: 18302 | Q23: 17373 | GR23: =IF(LEN(Folders!$A23)>0,Folders!$A23,"") -> P2D9
A24: IE | B24: 329 | C24: 선정/제외기준 | D24: TRUE | F24: FALSE | G24: TRUE | H24: FALSE | K24: Landscape | L24: MustNotDDE | P24: 18306 | Q24: 17375 | GR24: =IF(LEN(Folders!$A24)>0,Folders!$A24,"") -> PSV
A25: SU2 | B25: 663 | C25: 생활습관 확인 | D25: TRUE | F25: FALSE | G25: TRUE | H25: FALSE | K25: Landscape | L25: MustNotDDE | P25: 18323 | Q25: 17391 | GR25: =IF(LEN(Folders!$A25)>0,Folders!$A25,"") -> SCRN
A26: EX1 | B26: 664 | C26: 고지방 식사 | D26: TRUE | F26: FALSE | G26: TRUE | H26: FALSE | L26: MustNotDDE | P26: 18304 | Q26: 17268 | GR26: =IF(LEN(Folders!$A26)>0,Folders!$A26,"") -> UV
A27: EX | B27: 720 | C27: 임상시험용의약품 투여 | D27: TRUE | F27: FALSE | G27: TRUE | H27: FALSE | L27: MustNotDDE | P27: 18303 | Q27: 17374 | GR27: =IF(LEN(Folders!$A27)>0,Folders!$A27,"")
A28: PC1 | B28: 1182 | C28: 약동학 채혈 (0h-12h) | D28: TRUE | F28: FALSE | G28: TRUE | H28: FALSE | K28: Landscape | L28: MustNotDDE | P28: 18314 | Q28: 17383 | GR28: =IF(LEN(Folders!$A28)>0,Folders!$A28,"")
A29: PC2 | B29: 1183 | C29: 약동학 채혈 (24h) | D29: TRUE | F29: FALSE | G29: TRUE | H29: FALSE | K29: Landscape | L29: MustNotDDE | P29: 18315 | Q29: 17384 | GR29: =IF(LEN(Folders!$A29)>0,Folders!$A29,"")
A30: PC3 | B30: 1184 | C30: 약동학 채혈 (36h) | D30: TRUE | F30: FALSE | G30: TRUE | H30: FALSE | K30: Landscape | L30: MustNotDDE | P30: 18316 | Q30: 17385 | GR30: =IF(LEN(Folders!$A30)>0,Folders!$A30,"")
A31: PC4 | B31: 1185 | C31: 약동학 채혈 (48h) | D31: TRUE | F31: FALSE | G31: TRUE | H31: FALSE | K31: Landscape | L31: MustNotDDE | P31: 18317 | Q31: 17395 | GR31: =IF(LEN(Folders!$A31)>0,Folders!$A31,"")
A32: AE | B32: 1760 | C32: 이상반응 | D32: TRUE | F32: FALSE | G32: TRUE | H32: FALSE | K32: Portrait | L32: MustNotDDE | P32: 18291 | Q32: 17363 | GR32: =IF(LEN(Folders!$A32)>0,Folders!$A32,"")
A33: CM | B33: 1761 | C33: 병용약물 | D33: TRUE | F33: FALSE | G33: TRUE | H33: FALSE | K33: Portrait | L33: MustNotDDE | P33: 18294 | Q33: 17365 | GR33: =IF(LEN(Folders!$A33)>0,Folders!$A33,"")
A34: DVYN | B34: 1811 | C34: 누락 및 변경사항 확인 | D34: TRUE | F34: FALSE | G34: TRUE | H34: FALSE | L34: MustNotDDE | P34: 18301 | Q34: 17372 | GR34: =IF(LEN(Folders!$A34)>0,Folders!$A34,"")
A35: DV | B35: 1812 | C35: 누락 및 변경사항 | D35: TRUE | F35: FALSE | G35: TRUE | H35: FALSE | K35: Portrait | L35: MustNotDDE | P35: 18300 | Q35: 17371 | GR35: =IF(LEN(Folders!$A35)>0,Folders!$A35,"")
A36: DS3 | B36: 1923 | C36: 증례결론 | D36: TRUE | F36: FALSE | G36: TRUE | H36: FALSE | L36: MustNotDDE | P36: 18299 | Q36: 17370 | GR36: =IF(LEN(Folders!$A36)>0,Folders!$A36,"")
GR37: =IF(LEN(Folders!$A37)>0,Folders!$A37,"")
GR38: =IF(LEN(Folders!$A38)>0,Folders!$A38,"")
GR39: =IF(LEN(Folders!$A39)>0,Folders!$A39,"")
GR40: =IF(LEN(Folders!$A40)>0,Folders!$A40,"")
...

Sheet Fields
A1: FormOID | B1: FieldOID | C1: Ordinal | D1: DraftFieldNumber | E1: DraftFieldName | F1: DraftFieldActive | G1: VariableOID | H1: DataFormat | I1: DataDictionaryName | J1: UnitDictionaryName | K1: CodingDictionary | L1: ControlType | M1: AcceptableFileExtensions | N1: IndentLevel | O1: PreText | P1: FixedUnit | Q1: HeaderText | R1: HelpText | S1: SourceDocument | T1: IsLog | U1: DefaultValue | V1: SASLabel | W1: SASFormat | X1: EproFormat | Y1: IsRequired | Z1: QueryFutureDate | AA1: IsVisible | AB1: IsTranslationRequired | AC1: AnalyteName | AD1: IsClinicalSignificance | AE1: QueryNonConformance | AF1: OtherVisits | AG1: CanSetRecordDate | AH1: CanSetDataPageDate | AI1: CanSetInstanceDate | AJ1: CanSetSubjectDate | AK1: DoesNotBreakSignature | AL1: LowerRange | AM1: UpperRange | AN1: NCLowerRange | AO1: NCUpperRange | AP1: ViewRestrictions | AQ1: EntryRestrictions | AR1: ReviewGroups | AS1: IsVisualVerify | AT1: FDownloadedFromObjectId | AU1: FSourceObjectId | AV1: VDownloadedFromObjectId | AW1: VSourceObjectId | AX1: FSourceUrlId | AY1: VSourceUrlId | AZ1: AnalyteName_ValCol
A2: SUBJECT | B2: SUBJINT | C2: 1 | E2: SUBJINT | F2: TRUE | G2: SUBJINT | H2: $4 | L2: Text | N2: 0 | O2: 대상자 이니셜 | S2: TRUE | T2: FALSE | Y2: TRUE | Z2: FALSE | AA2: TRUE | AB2: FALSE | AD2: FALSE | AE2: FALSE | AF2: FALSE | AG2: FALSE | AH2: FALSE | AI2: FALSE | AJ2: FALSE | AK2: FALSE | AR2: Data Management | AS2: FALSE | AT2: 154779 | AU2: 0 | AV2: 124243 | AW2: 0 | AZ2: WBC | GR2: =IF(LEN(UnitDictionaries!$A2)>0,UnitDictionaries!$A2,"") | GS2: =IF(LEN(Forms!$A2)>0,Forms!$A2,"") -> SUBJECT | GT2: =IF(LEN(DataDictionaries!$A2)>0,DataDictionaries!$A2,"") -> AEACN
A3: SUBJECT | B3: SCRNO | C3: 2 | E3: SCRNO | F3: TRUE | G3: SCRNO | H3: $3 | L3: Text | N3: 0 | O3: 스크리닝 번호 | S3: TRUE | T3: FALSE | Y3: TRUE | Z3: FALSE | AA3: TRUE | AB3: FALSE | AD3: FALSE | AE3: FALSE | AF3: FALSE | AG3: FALSE | AH3: FALSE | AI3: FALSE | AJ3: FALSE | AK3: FALSE | AR3: Data Management | AS3: FALSE | AT3: 154778 | AU3: 147770 | AV3: 124070 | AW3: 118891 | AZ3: RBC | GR3: =IF(LEN(UnitDictionaries!$A3)>0,UnitDictionaries!$A3,"") | GS3: =IF(LEN(Forms!$A3)>0,Forms!$A3,"") -> DS1 | GT3: =IF(LEN(DataDictionaries!$A3)>0,DataDictionaries!$A3,"") -> AEACNOTH
A4: DS1 | B4: DSTERM | C4: 1 | E4: DSTERM | F4: TRUE | G4: DS1TERM | H4: $10 | L4: Text | N4: 0 | O4: 항목 | S4: FALSE | T4: TRUE | U4: 스크리닝 방문일|동의취득일| | Y4: FALSE | Z4: FALSE | AA4: TRUE | AB4: FALSE | AD4: FALSE | AE4: FALSE | AF4: FALSE | AG4: FALSE | AH4: FALSE | AI4: FALSE | AJ4: FALSE | AK4: TRUE | AQ4: Coder Import Role,Clinical Research Associate,Clinical Research Coordinator,Clinical Research Coordinator - IVRS,Coder,Data Manager,Investigator,Investigator - IVRS,Monitoring Data Manager,Outputs Locked,Outputs Standard,Power User,Rave Web Services (RWS),Read Only,Read Only - All Sites,Safety,Sub Investigator | AS4: FALSE | AT4: 154576 | AU4: 147586 | AV4: 124071 | AW4: 118892 | AZ4: HGB | GR4: =IF(LEN(UnitDictionaries!$A4)>0,UnitDictionaries!$A4,"") | GS4: =IF(LEN(Forms!$A4)>0,Forms!$A4,"") -> DM | GT4: =IF(LEN(DataDictionaries!$A4)>0,DataDictionaries!$A4,"") -> AEOUT
A5: DS1 | B5: DSDTC | C5: 2 | E5: DSDTC | F5: TRUE | G5: DSDTC | H5: yyyy/mm/dd | L5: DateTime | N5: 0 | O5: 날짜(YYYY/MM/DD) | S5: TRUE | T5: TRUE | Y5: TRUE | Z5: TRUE | AA5: TRUE | AB5: FALSE | AD5: FALSE | AE5: TRUE | AF5: FALSE | AG5: FALSE | AH5: FALSE | AI5: FALSE | AJ5: FALSE | AK5: FALSE | AR5: Data Management | AS5: FALSE | AT5: 154575 | AU5: 147585 | AV5: 124072 | AW5: 118893 | AZ5: HCT | GR5: =IF(LEN(UnitDictionaries!$A5)>0,UnitDictionaries!$A5,"") | GS5: =IF(LEN(Forms!$A5)>0,Forms!$A5,"") -> HO | GT5: =IF(LEN(DataDictionaries!$A5)>0,DataDictionaries!$A5,"") -> AEREL
A6: DM | B6: DMDTC | C6: 1 | E6: DMDTC | F6: TRUE | G6: DATE | H6: yyyy/mm/dd | L6: DateTime | N6: 0 | O6: 수행일(YYYY/MM/DD) | S6: TRUE | T6: FALSE | Y6: TRUE | Z6: TRUE | AA6: TRUE | AB6: FALSE | AD6: FALSE | AE6: TRUE | AF6: FALSE | AG6: FALSE | AH6: FALSE | AI6: FALSE | AJ6: FALSE | AK6: FALSE | AR6: Data Management | AS6: FALSE | AT6: 154564 | AU6: 147576 | AV6: 124073 | AW6: 118894 | AZ6: PLAT | GR6: =IF(LEN(UnitDictionaries!$A6)>0,UnitDictionaries!$A6,"") | GS6: =IF(LEN(Forms!$A6)>0,Forms!$A6,"") -> DS2 | GT6: =IF(LEN(DataDictionaries!$A6)>0,DataDictionaries!$A6,"") -> AESER
A7: DM | B7: SEX | C7: 2 | E7: SEX | F7: TRUE | G7: SEX | H7: 1 | I7: SEX | L7: DropDownList | N7: 0 | O7: 성별 | S7: TRUE | T7: FALSE | Y7: TRUE | Z7: FALSE | AA7: TRUE | AB7: FALSE | AD7: FALSE | AE7: FALSE | AF7: FALSE | AG7: FALSE | AH7: FALSE | AI7: FALSE | AJ7: FALSE | AK7: FALSE | AR7: Data Management | AS7: FALSE | AT7: 154570 | AU7: 147582 | AV7: 124074 | AW7: 118895 | AZ7: LYM | GR7: =IF(LEN(UnitDictionaries!$A7)>0,UnitDictionaries!$A7,"") | GS7: =IF(LEN(Forms!$A7)>0,Forms!$A7,"") -> MH | GT7: =IF(LEN(DataDictionaries!$A7)>0,DataDictionaries!$A7,"") -> AESEV
A8: DM | B8: SUB_HEADER | C8: 3 | E8: SUB_HEADER | F8: TRUE | L8: Text | N8: 0 | O8: ▶ 성별이 '여'인 경우 아래 해당되는 항목에 체크하십시오. | S8: FALSE | T8: FALSE | Y8: FALSE | Z8: FALSE | AA8: TRUE | AB8: FALSE | AD8: FALSE | AE8: FALSE | AF8: FALSE | AG8: FALSE | AH8: FALSE | AI8: FALSE | AJ8: FALSE | AK8: TRUE | AS8: FALSE | AT8: 154572 | AU8: 0 | AZ8: MONO | GR8: =IF(LEN(UnitDictionaries!$A8)>0,UnitDictionaries!$A8,"") | GS8: =IF(LEN(Forms!$A8)>0,Forms!$A8,"") -> SU1 | GT8: =IF(LEN(DataDictionaries!$A8)>0,DataDictionaries!$A8,"") -> ARMCD
A9: DM | B9: SEXORRES | C9: 4 | E9: SEXORRES | F9: TRUE | G9: SEXORRES | H9: 1 | I9: SEXORRES | L9: SearchList | N9: 0 | O9: '여'인 경우<br/>▶ '비가임 여성'인 경우 세부내용을 기재하여 주십시오. | S9: TRUE | T9: FALSE | Y9: FALSE | Z9: FALSE | AA9: FALSE | AB9: FALSE | AD9: FALSE | AE9: FALSE | AF9: FALSE | AG9: FALSE | AH9: FALSE | AI9: FALSE | AJ9: FALSE | AK9: FALSE | AR9: Data Management | AS9: FALSE | AT9: 154571 | AU9: 0 | AV9: 124238 | AW9: 0 | AZ9: NEUT | GR9: =IF(LEN(UnitDictionaries!$A9)>0,UnitDictionaries!$A9,"") | GS9: =IF(LEN(Forms!$A9)>0,Forms!$A9,"") -> SU | GT9: =IF(LEN(DataDictionaries!$A9)>0,DataDictionaries!$A9,"") -> RPORRES
A10: DM | B10: BRTHDTC | C10: 5 | E10: BRTHDTC | F10: TRUE | G10: BRTHDTC | H10: yyyy/mm/dd | L10: DateTime | N10: 0 | O10: 생년월일(YYYY/MM/DD) | S10: TRUE | T10: FALSE | Y10: TRUE | Z10: TRUE | AA10: TRUE | AB10: FALSE | AD10: FALSE | AE10: TRUE | AF10: FALSE | AG10: FALSE | AH10: FALSE | AI10: FALSE | AJ10: FALSE | AK10: FALSE | AR10: Data Management | AS10: FALSE | AT10: 154563 | AU10: 147575 | AV10: 124075 | AW10: 118896 | AZ10: EOS | GR10: =IF(LEN(UnitDictionaries!$A10)>0,UnitDictionaries!$A10,"") | GS10: =IF(LEN(Forms!$A10)>0,Forms!$A10,"") -> QS | GT10: =IF(LEN(DataDictionaries!$A10)>0,DataDictionaries!$A10,"") -> CLSIG1
A11: DM | B11: AGE | C11: 6 | E11: AGE | F11: TRUE | G11: AGE | H11: 2 | L11: Text | N11: 0 | O11: 연령(자동계산) | S11: TRUE | T11: FALSE | Y11: FALSE | Z11: FALSE | AA11: TRUE | AB11: FALSE | AD11: FALSE | AE11: TRUE | AF11: FALSE | AG11: FALSE | AH11: FALSE | AI11: FALSE | AJ11: FALSE | AK11: FALSE | AR11: Data Management | AS11: FALSE | AT11: 154561 | AU11: 147573 | AV11: 124076 | AW11: 118897 | AZ11: BASO | GR11: =IF(LEN(UnitDictionaries!$A11)>0,UnitDictionaries!$A11,"") | GS11: =IF(LEN(Forms!$A11)>0,Forms!$A11,"") -> VS | GT11: =IF(LEN(DataDictionaries!$A11)>0,DataDictionaries!$A11,"") -> CMDOSU
A12: DM | B12: AGEU | C12: 7 | E12: AGEU | F12: TRUE | G12: AGEU | H12: $10 | L12: Text | N12: 0 | O12: 연령 단위 | S12: FALSE | T12: FALSE | U12: 세(만) | Y12: FALSE | Z12: FALSE | AA12: TRUE | AB12: FALSE | AD12: FALSE | AE12: FALSE | AF12: FALSE | AG12: FALSE | AH12: FALSE | AI12: FALSE | AJ12: FALSE | AK12: TRUE | AQ12: Coder Import Role,Clinical Research Associate,Clinical Research Coordinator,Clinical Research Coordinator - IVRS,Coder,Data Manager,Investigator,Investigator - IVRS,Monitoring Data Manager,Outputs Locked,Outputs Standard,Power User,Rave Web Services (RWS),Read Only,Read Only - All Sites,Safety,Sub Investigator | AS12: FALSE | AT12: 154562 | AU12: 147574 | AV12: 124077 | AW12: 118898 | AZ12: SODIUM | GR12: =IF(LEN(UnitDictionaries!$A12)>0,UnitDictionaries!$A12,"") | GS12: =IF(LEN(Forms!$A12)>0,Forms!$A12,"") -> PE | GT12: =IF(LEN(DataDictionaries!$A12)>0,DataDictionaries!$A12,"") -> CMROUTE
A13: DM | B13: HEIGHT | C13: 8 | E13: HEIGHT | F13: TRUE | G13: HEIGHT | H13: 8.3 | L13: Text | N13: 0 | O13: 신장 | S13: TRUE | T13: FALSE | Y13: TRUE | Z13: FALSE | AA13: TRUE | AB13: FALSE | AD13: FALSE | AE13: FALSE | AF13: FALSE | AG13: FALSE | AH13: FALSE | AI13: FALSE | AJ13: FALSE | AK13: FALSE | AL13: 100 | AM13: 200 | AR13: Data Management | AS13: FALSE | AT13: 154566 | AU13: 147578 | AV13: 124078 | AW13: 118899 | AZ13: K | GR13: =IF(LEN(UnitDictionaries!$A13)>0,UnitDictionaries!$A13,"") | GS13: =IF(LEN(Forms!$A13)>0,Forms!$A13,"") -> AEYN | GT13: =IF(LEN(DataDictionaries!$A13)>0,DataDictionaries!$A13,"") -> DSDECOD
A14: DM | B14: HEIGHTU | C14: 9 | E14: HEIGHTU | F14: TRUE | G14: HEIGHTU | H14: $10 | L14: Text | N14: 0 | O14: 신장 단위 | S14: FALSE | T14: FALSE | U14: cm | Y14: FALSE | Z14: FALSE | AA14: TRUE | AB14: FALSE | AD14: FALSE | AE14: FALSE | AF14: FALSE | AG14: FALSE | AH14: FALSE | AI14: FALSE | AJ14: FALSE | AK14: TRUE | AQ14: Coder Import Role,Clinical Research Associate,Clinical Research Coordinator,Clinical Research Coordinator - IVRS,Coder,Data Manager,Investigator,Investigator - IVRS,Monitoring Data Manager,Outputs Locked,Outputs Standard,Power User,Rave Web Services (RWS),Read Only,Read Only - All Sites,Safety,Sub Investigator | AS14: FALSE | AT14: 154567 | AU14: 147579 | AV14: 124079 | AW14: 118900 | AZ14: CL | GR14: =IF(LEN(UnitDictionaries!$A14)>0,UnitDictionaries!$A14,"") | GS14: =IF(LEN(Forms!$A14)>0,Forms!$A14,"") -> CMYN | GT14: =IF(LEN(DataDictionaries!$A14)>0,DataDictionaries!$A14,"") -> DSDTC
A15: DM | B15: WEIGHT | C15: 10 | E15: WEIGHT | F15: TRUE | G15: WEIGHT | H15: 8.3 | L15: Text | N15: 0 | O15: 체중 | S15: TRUE | T15: FALSE | Y15: TRUE | Z15: FALSE | AA15: TRUE | AB15: FALSE | AD15: FALSE | AE15: FALSE | AF15: FALSE | AG15: FALSE | AH15: FALSE | AI15: FALSE | AJ15: FALSE | AK15: FALSE | AL15: 50 | AM15: 100 | AR15: Data Management | AS15: FALSE | AT15: 154573 | AU15: 147583 | AV15: 124080 | AW15: 118901 | AZ15: ALP | GR15: =IF(LEN(UnitDictionaries!$A15)>0,UnitDictionaries!$A15,"") | GS15: =IF(LEN(Forms!$A15)>0,Forms!$A15,"") -> LBHE | GT15: =IF(LEN(DataDictionaries!$A15)>0,DataDictionaries!$A15,"") -> DVDECOD
A16: DM | B16: WEIGHTU | C16: 11 | E16: WEIGHTU | F16: TRUE | G16: WEIGHTU | H16: $10 | L16: Text | N16: 0 | O16: 체중 단위 | S16: FALSE | T16: FALSE | U16: kg | Y16: FALSE | Z16: FALSE | AA16: TRUE | AB16: FALSE | AD16: FALSE | AE16: FALSE | AF16: FALSE | AG16: FALSE | AH16: FALSE | AI16: FALSE | AJ16: FALSE | AK16: TRUE | AQ16: Coder Import Role,Clinical Research Associate,Clinical Research Coordinator,Clinical Research Coordinator - IVRS,Coder,Data Manager,Investigator,Investigator - IVRS,Monitoring Data Manager,Outputs Locked,Outputs Standard,Power User,Rave Web Services (RWS),Read Only,Read Only - All Sites,Safety,Sub Investigator | AS16: FALSE | AT16: 154574 | AU16: 147584 | AV16: 124081 | AW16: 118902 | AZ16: AST | GR16: =IF(LEN(UnitDictionaries!$A16)>0,UnitDictionaries!$A16,"") | GS16: =IF(LEN(Forms!$A16)>0,Forms!$A16,"") -> LBCH | GT16: =IF(LEN(DataDictionaries!$A16)>0,DataDictionaries!$A16,"") -> EGTEST
A17: DM | B17: IBW | C17: 12 | E17: IBW | F17: TRUE | G17: IBW | H17: 3.1+ | L17: Text | N17: 0 | O17: 이상체중(IBW)(자동계산) | S17: FALSE | T17: FALSE | Y17: FALSE | Z17: FALSE | AA17: TRUE | AB17: FALSE | AD17: FALSE | AE17: FALSE | AF17: FALSE | AG17: FALSE | AH17: FALSE | AI17: FALSE | AJ17: FALSE | AK17: TRUE | AQ17: Coder Import Role,Clinical Research Associate,Clinical Research Coordinator,Clinical Research Coordinator - IVRS,Coder,Data Manager,Investigator,Investigator - IVRS,Monitoring Data Manager,Outputs Locked,Outputs Standard,Power User,Rave Web Services (RWS),Read Only,Read Only - All Sites,Safety,Sub Investigator | AS17: FALSE | AT17: 154568 | AU17: 147580 | AV17: 124082 | AW17: 118903 | AZ17: ALT | GR17: =IF(LEN(UnitDictionaries!$A17)>0,UnitDictionaries!$A17,"") | GS17: =IF(LEN(Forms!$A17)>0,Forms!$A17,"") -> LBUR | GT17: =IF(LEN(DataDictionaries!$A17)>0,DataDictionaries!$A17,"") -> EXTRT
A18: DM | B18: IBWU | C18: 13 | E18: IBWU | F18: TRUE | G18: IBWU | H18: $10 | L18: Text | N18: 0 | O18: 이상체중(IBW) 단위 | S18: FALSE | T18: FALSE | U18: kg | Y18: FALSE | Z18: FALSE | AA18: TRUE | AB18: FALSE | AD18: FALSE | AE18: FALSE | AF18: FALSE | AG18: FALSE | AH18: FALSE | AI18: FALSE | AJ18: FALSE | AK18: TRUE | AQ18: Coder Import Role,Clinical Research Associate,Clinical Research Coordinator,Clinical Research Coordinator - IVRS,Coder,Data Manager,Investigator,Investigator - IVRS,Monitoring Data Manager,Outputs Locked,Outputs Standard,Power User,Rave Web Services (RWS),Read Only,Read Only - All Sites,Safety,Sub Investigator | AS18: FALSE | AT18: 154569 | AU18: 147581 | AV18: 124083 | AW18: 118904 | AZ18: BILI_C | GR18: =IF(LEN(UnitDictionaries!$A18)>0,UnitDictionaries!$A18,"") | GS18: =IF(LEN(Forms!$A18)>0,Forms!$A18,"") -> LBUR2 | GT18: =IF(LEN(DataDictionaries!$A18)>0,DataDictionaries!$A18,"") -> EXYN
A19: DM | B19: HEADER | C19: 14 | E19: HEADER | F19: TRUE | L19: Text | N19: 0 | O19: ▶ IBW 계산식<br/>☞ 이상체중(IBW) = (신장 cm - 100) x 0.9 | S19: FALSE | T19: FALSE | Y19: FALSE | Z19: FALSE | AA19: TRUE | AB19: FALSE | AD19: FALSE | AE19: FALSE | AF19: FALSE | AG19: FALSE | AH19: FALSE | AI19: FALSE | AJ19: FALSE | AK19: TRUE | AQ19: Coder Import Role,Clinical Research Associate,Clinical Research Coordinator,Clinical Research Coordinator - IVRS,Coder,Data Manager,Investigator,Investigator - IVRS,Monitoring Data Manager,Outputs Locked,Outputs Standard,Power User,Rave Web Services (RWS),Read Only,Read Only - All Sites,Safety,Sub Investigator | AS19: FALSE | AT19: 154565 | AU19: 147577 | AZ19: PROT_C | GR19: =IF(LEN(UnitDictionaries!$A19)>0,UnitDictionaries!$A19,"") | GS19: =IF(LEN(Forms!$A19)>0,Forms!$A19,"") -> LBBC | GT19: =IF(LEN(DataDictionaries!$A19)>0,DataDictionaries!$A19,"") -> IETEST
A20: HO | B20: HODTC | C20: 1 | E20: HODTC | F20: TRUE | G20: HODTC | H20: yyyy/mm/dd | L20: DateTime | N20: 0 | O20: 입원일(YYYY/MM/DD) | S20: TRUE | T20: FALSE | Y20: TRUE | Z20: TRUE | AA20: TRUE | AB20: FALSE | AD20: FALSE | AE20: TRUE | AF20: FALSE | AG20: FALSE | AH20: FALSE | AI20: FALSE | AJ20: FALSE | AK20: FALSE | AR20: Data Management | AS20: FALSE | AT20: 154617 | AU20: 0 | AV20: 124244 | AW20: 0 | AZ20: ALB | GR20: =IF(LEN(UnitDictionaries!$A20)>0,UnitDictionaries!$A20,"") | GS20: =IF(LEN(Forms!$A20)>0,Forms!$A20,"") -> LBSE | GT20: =IF(LEN(DataDictionaries!$A20)>0,DataDictionaries!$A20,"") -> IEYN2
A21: DS2 | B21: DSSTAT | C21: 1 | E21: DSSTAT | F21: TRUE | G21: DSSTAT | H21: 1 | I21: YN1 | L21: DropDownList | N21: 0 | O21: 무작위배정번호를 부여하였습니까? | S21: TRUE | T21: FALSE | Y21: TRUE | Z21: FALSE | AA21: TRUE | AB21: FALSE | AD21: FALSE | AE21: FALSE | AF21: FALSE | AG21: FALSE | AH21: FALSE | AI21: FALSE | AJ21: FALSE | AK21: FALSE | AR21: Data Management | AS21: FALSE | AT21: 154579 | AU21: 147589 | AV21: 124084 | AW21: 118905 | AZ21: BUN | GR21: =IF(LEN(UnitDictionaries!$A21)>0,UnitDictionaries!$A21,"") | GS21: =IF(LEN(Forms!$A21)>0,Forms!$A21,"") -> RP | GT21: =IF(LEN(DataDictionaries!$A21)>0,DataDictionaries!$A21,"") -> LBSE1
A22: DS2 | B22: SUB_HEADER4 | C22: 2 | E22: SUB_HEADER4 | F22: TRUE | L22: Text | N22: 0 | O22: ▶ '예'인 경우 무작위배정번호 부여일, 순서군, 무작위배정번호를 기재하여 주십시오.<br/>▶ '아니오'인 경우 증례결론 페이지로 이동하여 기재하여 주십시오. | S22: FALSE | T22: FALSE | Y22: FALSE | Z22: FALSE | AA22: TRUE | AB22: FALSE | AD22: FALSE | AE22: FALSE | AF22: FALSE | AG22: FALSE | AH22: FALSE | AI22: FALSE | AJ22: FALSE | AK22: TRUE | AQ22: Coder Import Role,Clinical Research Associate,Clinical Research Coordinator,Clinical Research Coordinator - IVRS,Coder,Data Manager,Investigator,Investigator - IVRS,Monitoring Data Manager,Outputs Locked,Outputs Standard,Power User,Rave Web Services (RWS),Read Only,Read Only - All Sites,Safety,Sub Investigator | AS22: FALSE | AT22: 154580 | AU22: 147590 | AZ22: CREAT | GR22: =IF(LEN(UnitDictionaries!$A22)>0,UnitDictionaries!$A22,"") | GS22: =IF(LEN(Forms!$A22)>0,Forms!$A22,"") -> BST | GT22: =IF(LEN(DataDictionaries!$A22)>0,DataDictionaries!$A22,"") -> LBUR1
A23: DS2 | B23: DSDTC | C23: 3 | E23: DSDTC | F23: TRUE | G23: DS2DTC | H23: yyyy/mm/dd | L23: DateTime | N23: 0 | O23: 무작위배정번호 부여일(YYYY/MM/DD) | S23: TRUE | T23: FALSE | Y23: FALSE | Z23: TRUE | AA23: TRUE | AB23: FALSE | AD23: FALSE | AE23: TRUE | AF23: FALSE | AG23: FALSE | AH23: FALSE | AI23: FALSE | AJ23: FALSE | AK23: FALSE | AR23: Data Management | AS23: FALSE | AT23: 154578 | AU23: 147588 | AV23: 124100 | AW23: 118922 | AZ23: URATE | GR23: =IF(LEN(UnitDictionaries!$A23)>0,UnitDictionaries!$A23,"") | GS23: =IF(LEN(Forms!$A23)>0,Forms!$A23,"") -> EG | GT23: =IF(LEN(DataDictionaries!$A23)>0,DataDictionaries!$A23,"") -> LBUR2
A24: DS2 | B24: ARMCD | C24: 4 | E24: ARMCD | F24: TRUE | G24: ARMCD | H24: 1 | I24: ARMCD | L24: DropDownList | N24: 0 | O24: 순서군 | S24: TRUE | T24: FALSE | Y24: FALSE | Z24: FALSE | AA24: TRUE | AB24: FALSE | AD24: FALSE | AE24: FALSE | AF24: FALSE | AG24: FALSE | AH24: FALSE | AI24: FALSE | AJ24: FALSE | AK24: FALSE | AR24: Data Management | AS24: FALSE | AT24: 154577 | AU24: 147587 | AV24: 124101 | AW24: 118923 | AZ24: PHOS | GR24: =IF(LEN(UnitDictionaries!$A24)>0,UnitDictionaries!$A24,"") | GS24: =IF(LEN(Forms!$A24)>0,Forms!$A24,"") -> IE | GT24: =IF(LEN(DataDictionaries!$A24)>0,DataDictionaries!$A24,"") -> LBUR3
A25: DS2 | B25: USUBJID | C25: 5 | E25: USUBJID | F25: TRUE | G25: USUBJID | H25: $5 | L25: Text | N25: 0 | O25: 무작위배정번호 | S25: TRUE | T25: FALSE | Y25: FALSE | Z25: FALSE | AA25: TRUE | AB25: FALSE | AD25: FALSE | AE25: FALSE | AF25: FALSE | AG25: FALSE | AH25: FALSE | AI25: FALSE | AJ25: FALSE | AK25: FALSE | AR25: Data Management | AS25: FALSE | AT25: 154581 | AU25: 147591 | AV25: 124102 | AW25: 118924 | AZ25: CHOL | GR25: =IF(LEN(UnitDictionaries!$A25)>0,UnitDictionaries!$A25,"") | GS25: =IF(LEN(Forms!$A25)>0,Forms!$A25,"") -> SU2 | GT25: =IF(LEN(DataDictionaries!$A25)>0,DataDictionaries!$A25,"") -> MHBODYSYS
A26: MH | B26: MHDTC | C26: 1 | E26: MHDTC | F26: TRUE | G26: DATE | H26: yyyy/mm/dd | L26: DateTime | N26: 0 | O26: 수행일(YYYY/MM/DD) | S26: TRUE | T26: FALSE | Y26: TRUE | Z26: TRUE | AA26: TRUE | AB26: FALSE | AD26: FALSE | AE26: TRUE | AF26: FALSE | AG26: FALSE | AH26: FALSE | AI26: FALSE | AJ26: FALSE | AK26: FALSE | AR26: Data Management | AS26: FALSE | AT26: 154687 | AU26: 147691 | AV26: 124073 | AW26: 118894 | AZ26: GLUC_C | GR26: =IF(LEN(UnitDictionaries!$A26)>0,UnitDictionaries!$A26,"") | GS26: =IF(LEN(Forms!$A26)>0,Forms!$A26,"") -> EX1 | GT26: =IF(LEN(DataDictionaries!$A26)>0,DataDictionaries!$A26,"") -> MHENRTPT
A27: MH | B27: MHYN | C27: 2 | E27: MHYN | F27: TRUE | G27: MHYN | H27: 1 | I27: YN1 | L27: DropDownList | N27: 0 | O27: 병력 및 수술력 | S27: TRUE | T27: FALSE | Y27: TRUE | Z27: FALSE | AA27: TRUE | AB27: FALSE | AD27: FALSE | AE27: FALSE | AF27: FALSE | AG27: FALSE | AH27: FALSE | AI27: FALSE | AJ27: FALSE | AK27: FALSE | AR27: Data Management | AS27: FALSE | AT27: 154691 | AU27: 147695 | AV27: 124085 | AW27: 118906 | AZ27: SPGRAV | GR27: =IF(LEN(UnitDictionaries!$A27)>0,UnitDictionaries!$A27,"") | GS27: =IF(LEN(Forms!$A27)>0,Forms!$A27,"") -> EX | GT27: =IF(LEN(DataDictionaries!$A27)>0,DataDictionaries!$A27,"") -> ND
A28: MH | B28: SUB_HEADER1 | C28: 3 | E28: SUB_HEADER1 | F28: TRUE | L28: Text | N28: 0 | O28: ▶ '예'인 경우 아래내용을 기재하여 주십시오. | S28: FALSE | T28: FALSE | Y28: FALSE | Z28: FALSE | AA28: TRUE | AB28: FALSE | AD28: FALSE | AE28: FALSE | AF28: FALSE | AG28: FALSE | AH28: FALSE | AI28: FALSE | AJ28: FALSE | AK28: TRUE | AQ28: Coder Import Role,Clinical Research Associate,Clinical Research Coordinator,Clinical Research Coordinator - IVRS,Coder,Data Manager,Investigator,Investigator - IVRS,Monitoring Data Manager,Outputs Locked,Outputs Standard,Power User,Rave Web Services (RWS),Read Only,Read Only - All Sites,Safety,Sub Investigator | AS28: FALSE | AT28: 154693 | AU28: 147697 | AZ28: PH | GR28: =IF(LEN(UnitDictionaries!$A28)>0,UnitDictionaries!$A28,"") | GS28: =IF(LEN(Forms!$A28)>0,Forms!$A28,"") -> PC1 | GT28: =IF(LEN(DataDictionaries!$A28)>0,DataDictionaries!$A28,"") -> PCTPT
A29: MH | B29: MHBODYSYS | C29: 4 | E29: MHBODYSYS | F29: TRUE | G29: MHBODYSYS | H29: 2 | I29: MHBODYSYS | L29: SearchList | N29: 0 | O29: 항목 | S29: TRUE | T29: TRUE | Y29: FALSE | Z29: FALSE | AA29: TRUE | AB29: FALSE | AD29: FALSE | AE29: FALSE | AF29: FALSE | AG29: FALSE | AH29: FALSE | AI29: FALSE | AJ29: FALSE | AK29: FALSE | AR29: Data Management | AS29: FALSE | AT29: 154685 | AU29: 147689 | AV29: 124103 | AW29: 118925 | AZ29: WBC_Urine | GR29: =IF(LEN(UnitDictionaries!$A29)>0,UnitDictionaries!$A29,"") | GS29: =IF(LEN(Forms!$A29)>0,Forms!$A29,"") -> PC2 | GT29: =IF(LEN(DataDictionaries!$A29)>0,DataDictionaries!$A29,"") -> PECLSIG
A30: MH | B30: MHENRTPT | C30: 5 | E30: MHENRTPT | F30: TRUE | G30: MHENRTPT | H30: 1 | I30: MHENRTPT | L30: DropDownList | N30: 0 | O30: Past/Present | S30: TRUE | T30: TRUE | Y30: FALSE | Z30: FALSE | AA30: TRUE | AB30: FALSE | AD30: FALSE | AE30: FALSE | AF30: FALSE | AG30: FALSE | AH30: FALSE | AI30: FALSE | AJ30: FALSE | AK30: FALSE | AR30: Data Management | AS30: FALSE | AT30: 154688 | AU30: 147692 | AV30: 124104 | AW30: 118926 | AZ30: NITRITE | GR30: =IF(LEN(UnitDictionaries!$A30)>0,UnitDictionaries!$A30,"") | GS30: =IF(LEN(Forms!$A30)>0,Forms!$A30,"") -> PC3 | GT30: =IF(LEN(DataDictionaries!$A30)>0,DataDictionaries!$A30,"") -> PETEST
A31: MH | B31: MHTERM | C31: 6 | E31: MHTERM | F31: TRUE | G31: MHTERM | H31: $300 | K31: MedDRA (Coder) | L31: LongText | N31: 0 | O31: 진단명 또는 수술명 | S31: TRUE | T31: TRUE | Y31: FALSE | Z31: FALSE | AA31: TRUE | AB31: FALSE | AD31: FALSE | AE31: FALSE | AF31: FALSE | AG31: FALSE | AH31: FALSE | AI31: FALSE | AJ31: FALSE | AK31: FALSE | AR31: Data Management | AS31: FALSE | AT31: 154690 | AU31: 147694 | AV31: 124105 | AW31: 118927 | AZ31: PROT_U | GR31: =IF(LEN(UnitDictionaries!$A31)>0,UnitDictionaries!$A31,"") | GS31: =IF(LEN(Forms!$A31)>0,Forms!$A31,"") -> PC4 | GT31: =IF(LEN(DataDictionaries!$A31)>0,DataDictionaries!$A31,"") -> QSTEST
A32: MH | B32: MHSTDTC | C32: 9 | E32: MHSTDTC | F32: TRUE | G32: MHSTDTC | H32: yyyy/mm-/dd- | L32: DateTime | N32: 0 | O32: 진단일 또는 수술일(YYYY/MM/DD) | S32: TRUE | T32: TRUE | Y32: FALSE | Z32: TRUE | AA32: TRUE | AB32: FALSE | AD32: FALSE | AE32: TRUE | AF32: FALSE | AG32: FALSE | AH32: FALSE | AI32: FALSE | AJ32: FALSE | AK32: FALSE | AR32: Data Management | AS32: FALSE | AT32: 154689 | AU32: 147693 | AV32: 124106 | AW32: 118928 | AZ32: GLUC_U | GR32: =IF(LEN(UnitDictionaries!$A32)>0,UnitDictionaries!$A32,"") | GS32: =IF(LEN(Forms!$A32)>0,Forms!$A32,"") -> AE | GT32: =IF(LEN(DataDictionaries!$A32)>0,DataDictionaries!$A32,"") -> SEX
A33: MH | B33: MHCMT | C33: 13 | E33: MHCMT | F33: TRUE | G33: MHCMT | H33: $500 | L33: LongText | N33: 0 | O33: 소견 | S33: TRUE | T33: TRUE | Y33: FALSE | Z33: FALSE | AA33: TRUE | AB33: FALSE | AD33: FALSE | AE33: FALSE | AF33: FALSE | AG33: FALSE | AH33: FALSE | AI33: FALSE | AJ33: FALSE | AK33: FALSE | AR33: Data Management | AS33: FALSE | AT33: 154686 | AU33: 147690 | AV33: 124107 | AW33: 118929 | AZ33: KETONEBD | GR33: =IF(LEN(UnitDictionaries!$A33)>0,UnitDictionaries!$A33,"") | GS33: =IF(LEN(Forms!$A33)>0,Forms!$A33,"") -> CM | GT33: =IF(LEN(DataDictionaries!$A33)>0,DataDictionaries!$A33,"") -> SEXORRES
A34: MH | B34: SUB_HEADER | C34: 14 | E34: SUB_HEADER | F34: TRUE | L34: Text | N34: 0 | O34: ▶ 병력이 한 가지 이상일 경우 'Add a new Log line'을 사용하여 기재하여 주십시오. | S34: FALSE | T34: FALSE | Y34: FALSE | Z34: FALSE | AA34: TRUE | AB34: FALSE | AD34: FALSE | AE34: FALSE | AF34: FALSE | AG34: FALSE | AH34: FALSE | AI34: FALSE | AJ34: FALSE | AK34: TRUE | AS34: FALSE | AT34: 154692 | AU34: 147696 | AZ34: UROBIL | GR34: =IF(LEN(UnitDictionaries!$A34)>0,UnitDictionaries!$A34,"") | GS34: =IF(LEN(Forms!$A34)>0,Forms!$A34,"") -> DVYN | GT34: =IF(LEN(DataDictionaries!$A34)>0,DataDictionaries!$A34,"") -> SUCAT1
A35: SU1 | B35: SUDTC | C35: 1 | E35: SUDTC | F35: TRUE | G35: DATE | H35: yyyy/mm/dd | L35: DateTime | N35: 0 | O35: 수행일(YYYY/MM/DD) | S35: TRUE | T35: FALSE | Y35: TRUE | Z35: TRUE | AA35: TRUE | AB35: FALSE | AD35: FALSE | AE35: TRUE | AF35: FALSE | AG35: FALSE | AH35: FALSE | AI35: FALSE | AJ35: FALSE | AK35: FALSE | AR35: Data Management | AS35: FALSE | AT35: 154768 | AU35: 147760 | AV35: 124073 | AW35: 118894 | AZ35: BILI_U | GR35: =IF(LEN(UnitDictionaries!$A35)>0,UnitDictionaries!$A35,"") | GS35: =IF(LEN(Forms!$A35)>0,Forms!$A35,"") -> DV | GT35: =IF(LEN(DataDictionaries!$A35)>0,DataDictionaries!$A35,"") -> SUCAT2
A36: SU1 | B36: SUYN | C36: 2 | E36: SUYN | F36: TRUE | G36: SUYN | H36: 1 | I36: SUYN | L36: DropDownList | N36: 0 | O36: 항목 | S36: FALSE | T36: TRUE | U36: 1|2|3| | Y36: FALSE | Z36: FALSE | AA36: TRUE | AB36: FALSE | AD36: FALSE | AE36: FALSE | AF36: FALSE | AG36: FALSE | AH36: FALSE | AI36: FALSE | AJ36: FALSE | AK36: TRUE | AQ36: Coder Import Role,Clinical Research Associate,Clinical Research Coordinator,Clinical Research Coordinator - IVRS,Coder,Data Manager,Investigator,Investigator - IVRS,Monitoring Data Manager,Outputs Locked,Outputs Standard,Power User,Rave Web Services (RWS),Read Only,Read Only - All Sites,Safety,Sub Investigator | AS36: FALSE | AT36: 154771 | AU36: 147763 | AV36: 124108 | AW36: 118930 | AZ36: OCCBLD | GR36: =IF(LEN(UnitDictionaries!$A36)>0,UnitDictionaries!$A36,"") | GS36: =IF(LEN(Forms!$A36)>0,Forms!$A36,"") -> DS3 | GT36: =IF(LEN(DataDictionaries!$A36)>0,DataDictionaries!$A36,"") -> SUCAT3
A37: SU1 | B37: SURE | C37: 3 | E37: SURE | F37: TRUE | G37: SURE | H37: 1 | I37: YN1 | L37: DropDownList | N37: 0 | O37: 결과 | S37: TRUE | T37: TRUE | Y37: TRUE | Z37: FALSE | AA37: TRUE | AB37: FALSE | AD37: FALSE | AE37: FALSE | AF37: FALSE | AG37: FALSE | AH37: FALSE | AI37: FALSE | AJ37: FALSE | AK37: FALSE | AR37: Data Management | AS37: FALSE | AT37: 154769 | AU37: 147761 | AV37: 124086 | AW37: 118907 | AZ37: RBC count(UF) | GR37: =IF(LEN(UnitDictionaries!$A37)>0,UnitDictionaries!$A37,"") | GS37: =IF(LEN(Forms!$A37)>0,Forms!$A37,"") | GT37: =IF(LEN(DataDictionaries!$A37)>0,DataDictionaries!$A37,"") -> SUYN
A38: SU1 | B38: SUTERMOTH | C38: 4 | E38: SUTERMOTH | F38: TRUE | G38: SUTERMOTH | H38: $500 | L38: LongText | N38: 1 | O38: 세부내용 | S38: TRUE | T38: TRUE | Y38: FALSE | Z38: FALSE | AA38: TRUE | AB38: FALSE | AD38: FALSE | AE38: FALSE | AF38: FALSE | AG38: FALSE | AH38: FALSE | AI38: FALSE | AJ38: FALSE | AK38: FALSE | AR38: Data Management | AS38: FALSE | AT38: 154770 | AU38: 147762 | AV38: 124109 | AW38: 118931 | AZ38: WBC count(UF) | GR38: =IF(LEN(UnitDictionaries!$A38)>0,UnitDictionaries!$A38,"") | GS38: =IF(LEN(Forms!$A38)>0,Forms!$A38,"") | GT38: =IF(LEN(DataDictionaries!$A38)>0,DataDictionaries!$A38,"") -> SUYNOTH
A39: SU1 | B39: SUB_HEADER1 | C39: 5 | E39: SUB_HEADER1 | F39: TRUE | L39: Text | N39: 1 | O39: ▶ “예”인 경우 '세부내용'을 기재하여 주십시오. | S39: FALSE | T39: FALSE | Y39: FALSE | Z39: FALSE | AA39: TRUE | AB39: FALSE | AD39: FALSE | AE39: FALSE | AF39: FALSE | AG39: FALSE | AH39: FALSE | AI39: FALSE | AJ39: FALSE | AK39: TRUE | AQ39: Coder Import Role,Clinical Research Associate,Clinical Research Coordinator,Clinical Research Coordinator - IVRS,Coder,Data Manager,Investigator,Investigator - IVRS,Monitoring Data Manager,Outputs Locked,Outputs Standard,Power User,Rave Web Services (RWS),Read Only,Read Only - All Sites,Safety,Sub Investigator | AS39: FALSE | AT39: 154766 | AU39: 147758 | AZ39: EPIC | GR39: =IF(LEN(UnitDictionaries!$A39)>0,UnitDictionaries!$A39,"") | GS39: =IF(LEN(Forms!$A39)>0,Forms!$A39,"") | GT39: =IF(LEN(DataDictionaries!$A39)>0,DataDictionaries!$A39,"") -> VSPOS
A40: SU1 | B40: SUCMT | C40: 6 | E40: SUCMT | F40: TRUE | G40: SUCMT | H40: $500 | L40: LongText | N40: 1 | O40: 소견 | S40: TRUE | T40: FALSE | Y40: FALSE | Z40: FALSE | AA40: TRUE | AB40: FALSE | AD40: FALSE | AE40: FALSE | AF40: FALSE | AG40: FALSE | AH40: FALSE | AI40: FALSE | AJ40: FALSE | AK40: FALSE | AR40: Data Management | AS40: FALSE | AT40: 154767 | AU40: 147759 | AV40: 124110 | AW40: 118932 | AZ40: CASTS | GR40: =IF(LEN(UnitDictionaries!$A40)>0,UnitDictionaries!$A40,"") | GS40: =IF(LEN(Forms!$A40)>0,Forms!$A40,"") | GT40: =IF(LEN(DataDictionaries!$A40)>0,DataDictionaries!$A40,"") -> VSTEST
...

Sheet Folders
A1: OID | B1: Ordinal | C1: FolderName | D1: AccessDays | E1: StartWinDays | F1: Targetdays | G1: EndWinDays | H1: OverDueDays | I1: CloseDays | J1: ParentFolderOID | K1: IsReusable | L1: DownloadedFromObjectId | M1: SourceObjectId | N1: SourceUrlId
A2: AE | B2: 21 | C2: Adverse Events | K2: FALSE | L2: 11058 | M2: 10294
A3: CC | B3: 24 | C3: Case Conclusion | K3: FALSE | L3: 11059 | M3: 10295
A4: CM | B4: 22 | C4: Concomitant Medications | K4: FALSE | L4: 11060 | M4: 10296
A5: DV | B5: 23 | C5: Violation of Protocol | K5: FALSE | L5: 11061 | M5: 10297
A6: P1D0 | B6: 3 | C6: Period 1 Day 0 | K6: FALSE | L6: 11062 | M6: 10298
A7: P1D0H12 | B7: 7 | C7: Period 1 Day 0_12h | K7: FALSE | L7: 11063 | M7: 10299
A8: P1D0H2 | B8: 4 | C8: Period 1 Day 0_2h | K8: FALSE | L8: 11064 | M8: 10342
A9: P1D0H4 | B9: 5 | C9: Period 1 Day 0_4h | K9: FALSE | L9: 11065 | M9: 10300
A10: P1D0H8 | B10: 6 | C10: Period 1 Day 0_8h | K10: FALSE | L10: 11066 | M10: 10301
A11: P1D1H24 | B11: 8 | C11: Period 1 Day 1_24h | K11: FALSE | L11: 11067 | M11: 10302
A12: P1D1H36 | B12: 9 | C12: Period 1 Day 1_36h | K12: FALSE | L12: 11068 | M12: 10303
A13: P1D2 | B13: 10 | C13: Period 1 Day 2 | K13: FALSE | L13: 11069 | M13: 10304
... A26: UV | B26: 25 | C26: Unscheduled Visit | K26: FALSE | L26: 11082 | M26: 10316

Sheet DataDictionaries
A1: DataDictionaryName | B1: DownloadedFromObjectId | C1: SourceObjectId | D1: SourceUrlId
A2: AEACN | B2: 25823 | C2: 24640
A3: AEACNOTH | B3: 25824 | C3: 24641
A4: AEOUT | B4: 25825 | C4: 24642
A5: AEREL | B5: 25826 | C5: 24643
A6: AESER | B6: 25827 | C6: 24644
A7: AESEV | B7: 25828 | C7: 24645
A8: ARMCD | B8: 25829 | C8: 24646
A9: RPORRES | B9: 25830 | C9: 24647
A10: CLSIG1 | B10: 25831 | C10: 24648
A11: CMDOSU | B11: 25832 | C11: 24649
A12: CMROUTE | B12: 25833 | C12: 24650
A13: DSDECOD | B13: 25834 | C13: 24651
... A41: YN1 | B41: 25862 | C41: 24678

Sheet DataDictionaryEntries
A1: DataDictionaryName | B1: CodedData | C1: Ordinal | D1: UserDataString | E1: Specify
A2: AEACN | B2: 1 | C2: 1 | D2: 없음 (Not Done) | E2: FALSE | GR2: =IF(LEN(DataDictionaries!$A2)>0,DataDictionaries!$A2,"") -> AEACN
A3: AEACN | B3: 2 | C3: 2 | D3: 일시적 투여 중단(Stopped temporarily) | E3: FALSE | GR3: =IF(LEN(DataDictionaries!$A3)>0,DataDictionaries!$A3,"") -> AEACNOTH
A4: AEACN | B4: 3 | C4: 3 | D4: 영구 투여 중단(permanently discontinued) | E4: FALSE | GR4: =IF(LEN(DataDictionaries!$A4)>0,DataDictionaries!$A4,"") -> AEOUT
A5: AEACNOTH | B5: 1 | C5: 1 | D5: 취해진 조치 없음(No action taken) | E5: FALSE | GR5: =IF(LEN(DataDictionaries!$A5)>0,DataDictionaries!$A5,"") -> AEREL
A6: AEACNOTH | B6: 2 | C6: 2 | D6: 약물 치료(Concomitant medication taken) | E6: FALSE | GR6: =IF(LEN(DataDictionaries!$A6)>0,DataDictionaries!$A6,"") -> AESER
A7: AEACNOTH | B7: 3 | C7: 3 | D7: 비약물 치료(Non-drug therapy given) | E7: FALSE | GR7: =IF(LEN(DataDictionaries!$A7)>0,DataDictionaries!$A7,"") -> AESEV
A8: AEACNOTH | B8: 4 | C8: 4 | D8: 중도탈락(Withdrawn from study) | E8: FALSE | GR8: =IF(LEN(DataDictionaries!$A8)>0,DataDictionaries!$A8,"") -> ARMCD
A9: AEACNOTH | B9: 5 | C9: 5 | D9: 기타(Comments) | E9: TRUE | GR9: =IF(LEN(DataDictionaries!$A9)>0,DataDictionaries!$A9,"") -> RPORRES
A10: AEOUT | B10: 1 | C10: 1 | D10: 회복, 후유증 없음(Recovered without sequelae) | E10: FALSE | GR10: =IF(LEN(DataDictionaries!$A10)>0,DataDictionaries!$A10,"") -> CLSIG1
A11: AEOUT | B11: 2 | C11: 2 | D11: 회복, 후유증 있음(Recovered with sequelae) | E11: FALSE | GR11: =IF(LEN(DataDictionaries!$A11)>0,DataDictionaries!$A11,"") -> CMDOSU
A12: AEOUT | B12: 3 | C12: 3 | D12: 이상반응 지속(AE still exists) | E12: FALSE | GR12: =IF(LEN(DataDictionaries!$A12)>0,DataDictionaries!$A12,"") -> CMROUTE
A13: AEOUT | B13: 4 | C13: 4 | D13: 사망(Death) | E13: FALSE | GR13: =IF(LEN(DataDictionaries!$A13)>0,DataDictionaries!$A13,"") -> DSDECOD
... A220: YN1 | B220: 2 | C220: 2 | D220: 아니오 | E220: FALSE | GR220: =IF(LEN(DataDictionaries!$A220)>0,DataDictionaries!$A220,"")
GR221: =IF(LEN(DataDictionaries!$A221)>0,DataDictionaries!$A221,"")
GR222: =IF(LEN(DataDictionaries!$A222)>0,DataDictionaries!$A222,"")
GR223: =IF(LEN(DataDictionaries!$A223)>0,DataDictionaries!$A223,"")
GR224: =IF(LEN(DataDictionaries!$A224)>0,DataDictionaries!$A224,"")
GR225: =IF(LEN(DataDictionaries!$A225)>0,DataDictionaries!$A225,"")
GR226: =IF(LEN(DataDictionaries!$A226)>0,DataDictionaries!$A226,"")
GR227: =IF(LEN(DataDictionaries!$A227)>0,DataDictionaries!$A227,"")
GR228: =IF(LEN(DataDictionaries!$A228)>0,DataDictionaries!$A228,"")
GR229: =IF(LEN(DataDictionaries!$A229)>0,DataDictionaries!$A229,"")
GR230: =IF(LEN(DataDictionaries!$A230)>0,DataDictionaries!$A230,"")
GR231: =IF(LEN(DataDictionaries!$A231)>0,DataDictionaries!$A231,"")
GR232: =IF(LEN(DataDictionaries!$A232)>0,DataDictionaries!$A232,"")
... GR240: =IF(LEN(DataDictionaries!$A240)>0,DataDictionaries!$A240,"")

Sheet UnitDictionaries
A1: UnitDictionaryName | B1: StandardUnitName | C1: DownloadedFromObjectId | D1: SourceObjectId | E1: SourceUrlId
GR2: =IF(LEN(UnitDictionaryEntries!$H2)>0,UnitDictionaryEntries!$H2,"")
GR3: =IF(LEN(UnitDictionaryEntries!$H3)>0,UnitDictionaryEntries!$H3,"")
GR4: =IF(LEN(UnitDictionaryEntries!$H4)>0,UnitDictionaryEntries!$H4,"")
GR5: =IF(LEN(UnitDictionaryEntries!$H5)>0,UnitDictionaryEntries!$H5,"")
GR6: =IF(LEN(UnitDictionaryEntries!$H6)>0,UnitDictionaryEntries!$H6,"")
GR7: =IF(LEN(UnitDictionaryEntries!$H7)>0,UnitDictionaryEntries!$H7,"")
GR8: =IF(LEN(UnitDictionaryEntries!$H8)>0,UnitDictionaryEntries!$H8,"")
GR9: =IF(LEN(UnitDictionaryEntries!$H9)>0,UnitDictionaryEntries!$H9,"")
GR10: =IF(LEN(UnitDictionaryEntries!$H10)>0,UnitDictionaryEntries!$H10,"")
GR11: =IF(LEN(UnitDictionaryEntries!$H11)>0,UnitDictionaryEntries!$H11,"")
GR12: =IF(LEN(UnitDictionaryEntries!$H12)>0,UnitDictionaryEntries!$H12,"")
GR13: =IF(LEN(UnitDictionaryEntries!$H13)>0,UnitDictionaryEntries!$H13,"")
... GR22: =IF(LEN(UnitDictionaryEntries!$H22)>0,UnitDictionaryEntries!$H22,"")

Sheet UnitDictionaryEntries
A1: UnitDictionaryName | B1: CodedUnit | C1: Ordinal | D1: ConstantA | E1: ConstantB | F1: ConstantC | G1: ConstantK | H1: UnitString
GR2: =IF(LEN(UnitDictionaries!$A2)>0,UnitDictionaries!$A2,"")
GR3: =IF(LEN(UnitDictionaries!$A3)>0,UnitDictionaries!$A3,"")
GR4: =IF(LEN(UnitDictionaries!$A4)>0,UnitDictionaries!$A4,"")
GR5: =IF(LEN(UnitDictionaries!$A5)>0,UnitDictionaries!$A5,"")
GR6: =IF(LEN(UnitDictionaries!$A6)>0,UnitDictionaries!$A6,"")
GR7: =IF(LEN(UnitDictionaries!$A7)>0,UnitDictionaries!$A7,"")
GR8: =IF(LEN(UnitDictionaries!$A8)>0,UnitDictionaries!$A8,"")
GR9: =IF(LEN(UnitDictionaries!$A9)>0,UnitDictionaries!$A9,"")
GR10: =IF(LEN(UnitDictionaries!$A10)>0,UnitDictionaries!$A10,"")
GR11: =IF(LEN(UnitDictionaries!$A11)>0,UnitDictionaries!$A11,"")
GR12: =IF(LEN(UnitDictionaries!$A12)>0,UnitDictionaries!$A12,"")
GR13: =IF(LEN(UnitDictionaries!$A13)>0,UnitDictionaries!$A13,"")
... GR42: =IF(LEN(UnitDictionaries!$A42)>0,UnitDictionaries!$A42,"")

Sheet Matrices
A1: Matrix: ALL | B1: Subject | C1: SCRN | D1: P1DM1 | E1: P1D0 | F1: P1D0H2 | G1: P1D0H4 | H1: P1D0H8 | I1: P1D0H12 | J1: P1D1H24 | K1: P1D1H36 | L1: P1D2 | M1: P2D6 | N1: P2D7 | O1: P2D7H2 | P1: P2D7H4 | Q1: P2D7H8 | R1: P2D7H12 | S1: P2D8H24 | T1: P2D8H36 | U1: P2D9 | V1: PSV | W1: AE | X1: CM | Y1: DV | Z1: CC | AA1: UV
A2: SUBJECT
A3: DS1 | C3: X
A4: DM | C4: X
A5: HO | D5: X | M5: X
A6: DS2 | D6: X
A7: MH | C7: X | D7: X | E7: X
A8: SU1 | D8: X | M8: X
A9: SU | C9: X
A10: QS | C10: X
A11: VS | C11: X | D11: X | E11: X | G11: X | H11: X | I11: X | J11: X | K11: X | L11: X | M11: X | N11: X | P11: X | Q11: X | R11: X | S11: X | T11: X | U11: X | V11: X | AA11: X
A12: PE | C12: X | D12: X | E12: X | G12: X | H12: X | I12: X | J12: X | K12: X | L12: X | M12: X | N12: X | P12: X | Q12: X | R12: X | S12: X | T12: X | U12: X | V12: X | AA12: X
A13: AEYN | E13: X | F13: X | G13: X | H13: X | I13: X | J13: X | K13: X | L13: X | M13: X | N13: X | O13: X | P13: X | Q13: X | R13: X | S13: X | T13: X | U13: X | V13: X
A14: CMYN | D14: X | E14: X | G14: X | H14: X | I14: X | J14: X | K14: X | L14: X | M14: X | N14: X | P14: X | Q14: X | R14: X | S14: X | T14: X | U14: X | V14: X
A15: LBHE | C15: X | L15: X | U15: X | AA15: X
A16: LBCH | C16: X | L16: X | U16: X | AA16: X
A17: LBUR | C17: X | L17: X | U17: X | AA17: X
A18: LBUR2 | C18: X | L18: X | U18: X | AA18: X
A19: LBBC | C19: X | AA19: X
A20: LBSE | C20: X | AA20: X
A21: RP | C21: X | D21: X | M21: X | AA21: X
A22: BST | E22: X | F22: X | G22: X | N22: X | O22: X | P22: X | AA22: X
A23: EG | C23: X | L23: X | U23: X | AA23: X
A24: IE | C24: X
A25: SU2
A26: EX1 | E26: X | N26: X
A27: EX | E27: X | N27: X
A28: PC1 | E28: X | N28: X
A29: PC2 | J29: X | S29: X
A30: PC3 | K30: X | T30: X
A31: PC4 | L31: X | U31: X
A32: AE | W32: X
A33: CM | X33: X
A34: DVYN | Y34: X
A35: DV | Y35: X
A36: DS3 | Z36: X
